<?xml version="1.0" ?>
<!-- =================================================================================== -->
<!-- |    This document was autogenerated by xacro from /home/next/testBuild/src/ui_ws/urdf/robot.urdf.xacro | -->
<!-- |    EDITING THIS FILE BY HAND IS NOT RECOMMENDED                                 | -->
<!-- =================================================================================== -->
<robot name="robot">
  <!-- Specify some standard inertial calculations https://en.wikipedia.org/wiki/List_of_moments_of_inertia -->
  <!-- These make use of xacro's mathematical functionality -->
  <material name="white">
    <color rgba="1 1 1 1"/>
  </material>
  <material name="black">
    <color rgba="0 0 0 1"/>
  </material>
  <material name="red">
    <color rgba="1 0 0 1"/>
  </material>
  <link name="base_footprint"/>
  <joint name="base_footprint_joint" type="fixed">
    <parent link="base_footprint"/>
    <child link="base_link"/>
    <origin rpy="0 0 0" xyz="0 0 0.1"/>
  </joint>
  <link name="base_link">
    <visual>
      <origin xyz="0.0 0 0.045"/>
      <geometry>
        <box size="0.8 0.58 0.09"/>
      </geometry>
      <material name="white"/>
    </visual>
    <collision>
      <origin xyz="0.0 0 0.045"/>
      <geometry>
        <box size="0.8 0.58 0.09"/>
      </geometry>
    </collision>
    <inertial>
      <origin rpy="0 0 0" xyz="0.0 0 0.045"/>
      <mass value="40.0"/>
      <inertia ixx="1.1483333333333332" ixy="0.0" ixz="0.0" iyy="2.1603333333333334" iyz="0.0" izz="3.254666666666667"/>
    </inertial>
  </link>
  <gazebo reference="base_link">
    <material>Gazebo/White</material>
  </gazebo>
  <joint name="left_wheel_joint" type="continuous">
    <parent link="base_link"/>
    <child link="left_wheel"/>
    <origin rpy="-1.5707963267948966 0 0" xyz="0 0.255 0"/>
    <axis xyz="0 0 1"/>
  </joint>
  <link name="left_wheel">
    <visual>
      <geometry>
        <cylinder length="0.04" radius="0.1"/>
      </geometry>
      <material name="black"/>
    </visual>
    <collision>
      <geometry>
        <sphere radius="0.1"/>
      </geometry>
    </collision>
    <inertial>
      <origin rpy="0 0 0" xyz="0 0 0"/>
      <mass value="1.5"/>
      <inertia ixx="0.00395" ixy="0.0" ixz="0.0" iyy="0.00395" iyz="0.0" izz="0.0075000000000000015"/>
    </inertial>
  </link>
  <joint name="right_wheel_joint" type="continuous">
    <parent link="base_link"/>
    <child link="right_wheel"/>
    <origin rpy="1.5707963267948966 0 0" xyz="0 -0.255 0"/>
    <axis xyz="0 0 -1"/>
  </joint>
  <link name="right_wheel">
    <visual>
      <geometry>
        <cylinder length="0.04" radius="0.1"/>
      </geometry>
      <material name="black"/>
    </visual>
    <collision>
      <geometry>
        <sphere radius="0.1"/>
      </geometry>
    </collision>
    <inertial>
      <origin rpy="0 0 0" xyz="0 0 0"/>
      <mass value="1.5"/>
      <inertia ixx="0.00395" ixy="0.0" ixz="0.0" iyy="0.00395" iyz="0.0" izz="0.0075000000000000015"/>
    </inertial>
  </link>
  <joint name="caster_front_left_joint" type="fixed">
    <parent link="base_link"/>
    <child link="caster_front_left"/>
    <origin xyz="0.35 0.20 -0.062"/>
  </joint>
  <link name="caster_front_left">
    <visual>
      <geometry>
        <sphere radius="0.038"/>
      </geometry>
      <material name="red"/>
    </visual>
    <collision>
      <geometry>
        <sphere radius="0.038"/>
      </geometry>
    </collision>
    <inertial>
      <origin rpy="0 0 0" xyz="0 0 0"/>
      <mass value="0.4"/>
      <inertia ixx="0.00023104000000000004" ixy="0.0" ixz="0.0" iyy="0.00023104000000000004" iyz="0.0" izz="0.00023104000000000004"/>
    </inertial>
  </link>
  <joint name="caster_front_right_joint" type="fixed">
    <parent link="base_link"/>
    <child link="caster_front_right"/>
    <origin xyz="0.35 -0.20 -0.062"/>
  </joint>
  <link name="caster_front_right">
    <visual>
      <geometry>
        <sphere radius="0.038"/>
      </geometry>
      <material name="red"/>
    </visual>
    <collision>
      <geometry>
        <sphere radius="0.038"/>
      </geometry>
    </collision>
    <inertial>
      <origin rpy="0 0 0" xyz="0 0 0"/>
      <mass value="0.4"/>
      <inertia ixx="0.00023104000000000004" ixy="0.0" ixz="0.0" iyy="0.00023104000000000004" iyz="0.0" izz="0.00023104000000000004"/>
    </inertial>
  </link>
  <joint name="caster_rear_left_joint" type="fixed">
    <parent link="base_link"/>
    <child link="caster_rear_left"/>
    <origin xyz="-0.35000000000000003 0.20 -0.062"/>
  </joint>
  <link name="caster_rear_left">
    <visual>
      <geometry>
        <sphere radius="0.038"/>
      </geometry>
      <material name="red"/>
    </visual>
    <collision>
      <geometry>
        <sphere radius="0.038"/>
      </geometry>
    </collision>
    <inertial>
      <origin rpy="0 0 0" xyz="0 0 0"/>
      <mass value="0.4"/>
      <inertia ixx="0.00023104000000000004" ixy="0.0" ixz="0.0" iyy="0.00023104000000000004" iyz="0.0" izz="0.00023104000000000004"/>
    </inertial>
  </link>
  <joint name="caster_rear_right_joint" type="fixed">
    <parent link="base_link"/>
    <child link="caster_rear_right"/>
    <origin xyz="-0.35000000000000003 -0.20 -0.062"/>
  </joint>
  <link name="caster_rear_right">
    <visual>
      <geometry>
        <sphere radius="0.038"/>
      </geometry>
      <material name="red"/>
    </visual>
    <collision>
      <geometry>
        <sphere radius="0.038"/>
      </geometry>
    </collision>
    <inertial>
      <origin rpy="0 0 0" xyz="0 0 0"/>
      <mass value="0.4"/>
      <inertia ixx="0.00023104000000000004" ixy="0.0" ixz="0.0" iyy="0.00023104000000000004" iyz="0.0" izz="0.00023104000000000004"/>
    </inertial>
  </link>
  <joint name="imu_joint" type="fixed">
    <parent link="base_link"/>
    <child link="imu_link"/>
    <origin rpy="0 0 0" xyz="0.0 0 0.10"/>
  </joint>
  <link name="imu_link">
    <visual>
      <geometry>
        <box size="0.0538 0.0488 0.0252"/>
      </geometry>
      <material name="red"/>
    </visual>
    <collision>
      <geometry>
        <box size="0.0538 0.0488 0.0252"/>
      </geometry>
    </collision>
    <inertial>
      <mass value="0.01"/>
      <origin rpy="0 0 0" xyz="0 0 0"/>
      <inertia ixx="0.0001" ixy="0" ixz="0" iyy="0.0001" iyz="0" izz="0.0001"/>
    </inertial>
  </link>
  <!-- Custom Kinco Hardware Interface for ros2_control -->
  <ros2_control name="KincoMotorSystem" type="system">
    <hardware>
      <plugin>next_motor_interface/KincoHardwareInterface</plugin>
      <param name="can_interface_name">can0</param>
    </hardware>
    <joint name="left_wheel_joint">
      <command_interface name="velocity"/>
      <state_interface name="position"/>
      <state_interface name="velocity"/>
      <param name="motor_id">2</param>
    </joint>
    <joint name="right_wheel_joint">
      <command_interface name="velocity"/>
      <state_interface name="position"/>
      <state_interface name="velocity"/>
      <param name="motor_id">1</param>
    </joint>
  </ros2_control>
  <!-- Specify some standard inertial calculations https://en.wikipedia.org/wiki/List_of_moments_of_inertia -->
  <!-- These make use of xacro's mathematical functionality -->
  <!-- Pi = 3.14159 -->
  <joint name="laser_front_joint" type="fixed">
    <parent link="base_link"/>
    <child link="laser_front_frame"/>
    <origin rpy="0 0 3.14159" xyz="0.35 0 0.10"/>
  </joint>
  <link name="laser_front_frame">
    <visual>
      <geometry>
        <cylinder length="0.04" radius="0.05"/>
      </geometry>
      <material name="orange"/>
    </visual>
    <visual>
      <origin xyz="0 0 -0.05"/>
      <geometry>
        <cylinder length="0.1" radius="0.01"/>
      </geometry>
      <material name="orange"/>
    </visual>
    <collision>
      <geometry>
        <cylinder length="0.04" radius="0.05"/>
      </geometry>
    </collision>
    <inertial>
      <origin rpy="0 0 0" xyz="0 0 0"/>
      <mass value="0.1"/>
      <inertia ixx="7.583333333333335e-05" ixy="0.0" ixz="0.0" iyy="7.583333333333335e-05" iyz="0.0" izz="0.00012500000000000003"/>
    </inertial>
  </link>
  <joint name="laser_rear_joint" type="fixed">
    <parent link="base_link"/>
    <child link="laser_rear_frame"/>
    <origin rpy="0 0 0" xyz="-0.35 0 0.10"/>
  </joint>
  <link name="laser_rear_frame">
    <visual>
      <geometry>
        <cylinder length="0.04" radius="0.05"/>
      </geometry>
      <material name="orange"/>
    </visual>
    <visual>
      <origin xyz="0 0 -0.05"/>
      <geometry>
        <cylinder length="0.1" radius="0.01"/>
      </geometry>
      <material name="orange"/>
    </visual>
    <collision>
      <geometry>
        <cylinder length="0.04" radius="0.05"/>
      </geometry>
    </collision>
    <inertial>
      <origin rpy="0 0 0" xyz="0 0 0"/>
      <mass value="0.1"/>
      <inertia ixx="7.583333333333335e-05" ixy="0.0" ixz="0.0" iyy="7.583333333333335e-05" iyz="0.0" izz="0.00012500000000000003"/>
    </inertial>
  </link>
  <!--
  <gazebo reference="laser_front_frame">
    <material>Gazebo/Black</material>
    <sensor name="laser" type="ray">
      <pose>0 0 0 0 0 3.14</pose>
      <visualize>true</visualize>
      <update_rate>10</update_rate>
      <ray>
        <scan>
          <horizontal>
            <samples>180</samples>
            <min_angle>-1.57</min_angle>
            <max_angle>1.57</max_angle>
          </horizontal>
        </scan>
        <range>
          <min>0.3</min>
          <max>12</max>
        </range>
      </ray>

      <plugin name="laser_controller" filename="libgazebo_ros_ray_sensor.so">
        <ros>
          <argument>~/out:=scan</argument>
        </ros>
        <output_type>sensor_msgs/LaserScan</output_type>
        <frame_name>laser_front_frame</frame_name>
      </plugin>
    </sensor>
  </gazebo>
  -->
  <gazebo reference="laser_front_frame">
    <material>Gazebo/Black</material>
    <sensor name="laser" type="ray">
      <pose>0 0 0 0 0 3.14</pose>
      <visualize>true</visualize>
      <update_rate>10</update_rate>
      <ray>
        <scan>
          <horizontal>
            <samples>180</samples>
            <min_angle>-1.57</min_angle>
            <max_angle>1.57</max_angle>
          </horizontal>
        </scan>
        <range>
          <min>0.3</min>
          <max>12</max>
        </range>
      </ray>
      <plugin filename="libgazebo_ros_ray_sensor.so" name="laser_controller">
        <ros>
          <argument>~/out:=scan</argument>
        </ros>
        <output_type>sensor_msgs/LaserScan</output_type>
        <frame_name>laser_front_frame</frame_name>
      </plugin>
    </sensor>
  </gazebo>
  <gazebo reference="laser_rear_frame">
    <material>Gazebo/Black</material>
    <sensor name="laser_rear" type="ray">
      <pose>0 0 0 0 0 0</pose>
      <visualize>true</visualize>
      <update_rate>10</update_rate>
      <ray>
        <scan>
          <horizontal>
            <samples>180</samples>
            <min_angle>-1.57</min_angle>
            <max_angle>1.57</max_angle>
          </horizontal>
        </scan>
        <range>
          <min>0.3</min>
          <max>12</max>
        </range>
      </ray>
      <plugin filename="libgazebo_ros_ray_sensor.so" name="laser_controller_rear">
        <ros>
          <argument>~/out:=scan2</argument>
        </ros>
        <output_type>sensor_msgs/LaserScan</output_type>
        <frame_name>laser_rear_frame</frame_name>
      </plugin>
    </sensor>
  </gazebo>
  <!-- <xacro:include filename="imu2.xacro" /> -->
  <!-- <xacro:include filename="camera.xacro" /> -->
  <!-- <xacro:include filename="depth_camera.xacro" /> -->
  <joint name="face_joint" type="fixed">
    <parent link="base_link"/>
    <child link="face_link"/>
    <origin rpy="0 0 0" xyz="0.4 0 0.045"/>
  </joint>
  <link name="face_link">
    <visual>
      <origin rpy="0 1.5707963267948966 0" xyz="0 0.05 0.01"/>
      <geometry>
        <cylinder length="0.002" radius="0.01"/>
      </geometry>
      <material name="black"/>
    </visual>
    <visual>
      <origin rpy="0 1.5707963267948966 0" xyz="0 -0.05 0.01"/>
      <geometry>
        <cylinder length="0.002" radius="0.01"/>
      </geometry>
      <material name="black"/>
    </visual>
    <visual>
      <origin rpy="0 1.5 0" xyz="-0.011 0 -0.00"/>
      <geometry>
        <cylinder length="0.02" radius="0.04"/>
      </geometry>
      <material name="red"/>
    </visual>
  </link>
  <gazebo reference="face_link">
    <material>Gazebo/Black</material>
  </gazebo>
</robot>
